2021-05-03 13:53:47,296 INFO: uvo-reserves [in /home/sumbel/PycharmProjects/uvo-reserves-demo/app/__init__.py:77]
2021-05-03 13:53:47,299 INFO: uvo-reserves startup [in /home/sumbel/PycharmProjects/uvo-reserves-demo/app/__init__.py:98]
2021-05-03 13:53:47,299 INFO: uvo-reserves startup [in /home/sumbel/PycharmProjects/uvo-reserves-demo/app/__init__.py:98]
2021-05-03 13:54:40,311 ERROR: Exception on /api/users/1 [GET] [in /home/sumbel/PycharmProjects/uvo-reserves-demo/venv/lib/python3.6/site-packages/flask/app.py:1892]
Traceback (most recent call last):
  File "/home/sumbel/PycharmProjects/uvo-reserves-demo/venv/lib/python3.6/site-packages/flask/app.py", line 2447, in wsgi_app
    response = self.full_dispatch_request()
  File "/home/sumbel/PycharmProjects/uvo-reserves-demo/venv/lib/python3.6/site-packages/flask/app.py", line 1952, in full_dispatch_request
    rv = self.handle_user_exception(e)
  File "/home/sumbel/PycharmProjects/uvo-reserves-demo/venv/lib/python3.6/site-packages/flask_cors/extension.py", line 165, in wrapped_function
    return cors_after_request(app.make_response(f(*args, **kwargs)))
  File "/home/sumbel/PycharmProjects/uvo-reserves-demo/venv/lib/python3.6/site-packages/flask/app.py", line 1821, in handle_user_exception
    reraise(exc_type, exc_value, tb)
  File "/home/sumbel/PycharmProjects/uvo-reserves-demo/venv/lib/python3.6/site-packages/flask/_compat.py", line 39, in reraise
    raise value
  File "/home/sumbel/PycharmProjects/uvo-reserves-demo/venv/lib/python3.6/site-packages/flask/app.py", line 1950, in full_dispatch_request
    rv = self.dispatch_request()
  File "/home/sumbel/PycharmProjects/uvo-reserves-demo/venv/lib/python3.6/site-packages/flask/app.py", line 1936, in dispatch_request
    return self.view_functions[rule.endpoint](**req.view_args)
  File "/home/sumbel/PycharmProjects/uvo-reserves-demo/venv/lib/python3.6/site-packages/flask_login/utils.py", line 272, in decorated_view
    return func(*args, **kwargs)
TypeError: decorated_function() got an unexpected keyword argument 'id'
2021-05-03 13:54:40,311 ERROR: Exception on /api/users/1 [GET] [in /home/sumbel/PycharmProjects/uvo-reserves-demo/venv/lib/python3.6/site-packages/flask/app.py:1892]
Traceback (most recent call last):
  File "/home/sumbel/PycharmProjects/uvo-reserves-demo/venv/lib/python3.6/site-packages/flask/app.py", line 2447, in wsgi_app
    response = self.full_dispatch_request()
  File "/home/sumbel/PycharmProjects/uvo-reserves-demo/venv/lib/python3.6/site-packages/flask/app.py", line 1952, in full_dispatch_request
    rv = self.handle_user_exception(e)
  File "/home/sumbel/PycharmProjects/uvo-reserves-demo/venv/lib/python3.6/site-packages/flask_cors/extension.py", line 165, in wrapped_function
    return cors_after_request(app.make_response(f(*args, **kwargs)))
  File "/home/sumbel/PycharmProjects/uvo-reserves-demo/venv/lib/python3.6/site-packages/flask/app.py", line 1821, in handle_user_exception
    reraise(exc_type, exc_value, tb)
  File "/home/sumbel/PycharmProjects/uvo-reserves-demo/venv/lib/python3.6/site-packages/flask/_compat.py", line 39, in reraise
    raise value
  File "/home/sumbel/PycharmProjects/uvo-reserves-demo/venv/lib/python3.6/site-packages/flask/app.py", line 1950, in full_dispatch_request
    rv = self.dispatch_request()
  File "/home/sumbel/PycharmProjects/uvo-reserves-demo/venv/lib/python3.6/site-packages/flask/app.py", line 1936, in dispatch_request
    return self.view_functions[rule.endpoint](**req.view_args)
  File "/home/sumbel/PycharmProjects/uvo-reserves-demo/venv/lib/python3.6/site-packages/flask_login/utils.py", line 272, in decorated_view
    return func(*args, **kwargs)
TypeError: decorated_function() got an unexpected keyword argument 'id'
2021-05-03 13:57:16,214 INFO: uvo-reserves [in /home/sumbel/PycharmProjects/uvo-reserves-demo/app/__init__.py:77]
2021-05-03 13:57:16,214 INFO: uvo-reserves startup [in /home/sumbel/PycharmProjects/uvo-reserves-demo/app/__init__.py:98]
2021-05-03 13:57:16,214 INFO: uvo-reserves startup [in /home/sumbel/PycharmProjects/uvo-reserves-demo/app/__init__.py:98]
2021-05-03 13:59:30,728 INFO: uvo-reserves [in /home/sumbel/PycharmProjects/uvo-reserves-demo/app/__init__.py:77]
2021-05-03 13:59:30,729 INFO: uvo-reserves startup [in /home/sumbel/PycharmProjects/uvo-reserves-demo/app/__init__.py:98]
2021-05-03 13:59:30,729 INFO: uvo-reserves startup [in /home/sumbel/PycharmProjects/uvo-reserves-demo/app/__init__.py:98]
2021-05-03 14:00:10,388 INFO: uvo-reserves [in /home/sumbel/PycharmProjects/uvo-reserves-demo/app/__init__.py:77]
2021-05-03 14:00:10,388 INFO: uvo-reserves startup [in /home/sumbel/PycharmProjects/uvo-reserves-demo/app/__init__.py:98]
2021-05-03 14:00:10,388 INFO: uvo-reserves startup [in /home/sumbel/PycharmProjects/uvo-reserves-demo/app/__init__.py:98]
2021-05-03 14:00:58,559 INFO: uvo-reserves [in /home/sumbel/PycharmProjects/uvo-reserves-demo/app/__init__.py:77]
2021-05-03 14:00:58,561 INFO: uvo-reserves startup [in /home/sumbel/PycharmProjects/uvo-reserves-demo/app/__init__.py:98]
2021-05-03 14:00:58,561 INFO: uvo-reserves startup [in /home/sumbel/PycharmProjects/uvo-reserves-demo/app/__init__.py:98]
2021-05-03 14:02:08,925 INFO: uvo-reserves [in /home/sumbel/PycharmProjects/uvo-reserves-demo/app/__init__.py:77]
2021-05-03 14:02:08,925 INFO: uvo-reserves startup [in /home/sumbel/PycharmProjects/uvo-reserves-demo/app/__init__.py:98]
2021-05-03 14:02:08,925 INFO: uvo-reserves startup [in /home/sumbel/PycharmProjects/uvo-reserves-demo/app/__init__.py:98]
2021-05-03 14:02:11,673 ERROR: Exception on /api/users/1 [GET] [in /home/sumbel/PycharmProjects/uvo-reserves-demo/venv/lib/python3.6/site-packages/flask/app.py:1892]
Traceback (most recent call last):
  File "/home/sumbel/PycharmProjects/uvo-reserves-demo/venv/lib/python3.6/site-packages/flask/app.py", line 2447, in wsgi_app
    response = self.full_dispatch_request()
  File "/home/sumbel/PycharmProjects/uvo-reserves-demo/venv/lib/python3.6/site-packages/flask/app.py", line 1952, in full_dispatch_request
    rv = self.handle_user_exception(e)
  File "/home/sumbel/PycharmProjects/uvo-reserves-demo/venv/lib/python3.6/site-packages/flask_cors/extension.py", line 165, in wrapped_function
    return cors_after_request(app.make_response(f(*args, **kwargs)))
  File "/home/sumbel/PycharmProjects/uvo-reserves-demo/venv/lib/python3.6/site-packages/flask/app.py", line 1821, in handle_user_exception
    reraise(exc_type, exc_value, tb)
  File "/home/sumbel/PycharmProjects/uvo-reserves-demo/venv/lib/python3.6/site-packages/flask/_compat.py", line 39, in reraise
    raise value
  File "/home/sumbel/PycharmProjects/uvo-reserves-demo/venv/lib/python3.6/site-packages/flask/app.py", line 1950, in full_dispatch_request
    rv = self.dispatch_request()
  File "/home/sumbel/PycharmProjects/uvo-reserves-demo/venv/lib/python3.6/site-packages/flask/app.py", line 1936, in dispatch_request
    return self.view_functions[rule.endpoint](**req.view_args)
  File "/home/sumbel/PycharmProjects/uvo-reserves-demo/venv/lib/python3.6/site-packages/flask_login/utils.py", line 272, in decorated_view
    return func(*args, **kwargs)
  File "/home/sumbel/PycharmProjects/uvo-reserves-demo/app/helpers/decorators.py", line 12, in decorated_function
    return f(user_id)
  File "/home/sumbel/PycharmProjects/uvo-reserves-demo/app/api/profile.py", line 16, in get_profile
    return json.dumps([p.__dict__ for p in projects])
  File "/usr/lib/python3.6/json/__init__.py", line 231, in dumps
    return _default_encoder.encode(obj)
  File "/usr/lib/python3.6/json/encoder.py", line 199, in encode
    chunks = self.iterencode(o, _one_shot=True)
  File "/usr/lib/python3.6/json/encoder.py", line 257, in iterencode
    return _iterencode(o, 0)
  File "/usr/lib/python3.6/json/encoder.py", line 180, in default
    o.__class__.__name__)
TypeError: Object of type 'InstanceState' is not JSON serializable
