2021-05-11 09:07:01,598 INFO: uvo-reserves [in C:\Users\lolip\Desktop\Git projects\uvo-reserves-demo\app\__init__.py:80]
2021-05-11 09:07:01,604 INFO: uvo-reserves startup [in C:\Users\lolip\Desktop\Git projects\uvo-reserves-demo\app\__init__.py:101]
2021-05-11 09:07:01,604 INFO: uvo-reserves startup [in C:\Users\lolip\Desktop\Git projects\uvo-reserves-demo\app\__init__.py:101]
2021-05-11 09:07:25,738 INFO: uvo-reserves [in C:\Users\lolip\Desktop\Git projects\uvo-reserves-demo\app\__init__.py:80]
2021-05-11 09:07:25,739 INFO: uvo-reserves startup [in C:\Users\lolip\Desktop\Git projects\uvo-reserves-demo\app\__init__.py:101]
2021-05-11 09:07:25,739 INFO: uvo-reserves startup [in C:\Users\lolip\Desktop\Git projects\uvo-reserves-demo\app\__init__.py:101]
2021-05-11 09:07:34,099 INFO: uvo-reserves [in C:\Users\lolip\Desktop\Git projects\uvo-reserves-demo\app\__init__.py:80]
2021-05-11 09:07:34,100 INFO: uvo-reserves startup [in C:\Users\lolip\Desktop\Git projects\uvo-reserves-demo\app\__init__.py:101]
2021-05-11 09:07:34,100 INFO: uvo-reserves startup [in C:\Users\lolip\Desktop\Git projects\uvo-reserves-demo\app\__init__.py:101]
2021-05-11 09:07:49,586 INFO: uvo-reserves [in C:\Users\lolip\Desktop\Git projects\uvo-reserves-demo\app\__init__.py:80]
2021-05-11 09:07:49,587 INFO: uvo-reserves startup [in C:\Users\lolip\Desktop\Git projects\uvo-reserves-demo\app\__init__.py:101]
2021-05-11 09:07:49,587 INFO: uvo-reserves startup [in C:\Users\lolip\Desktop\Git projects\uvo-reserves-demo\app\__init__.py:101]
2021-05-11 09:07:55,216 INFO: uvo-reserves [in C:\Users\lolip\Desktop\Git projects\uvo-reserves-demo\app\__init__.py:80]
2021-05-11 09:07:55,217 INFO: uvo-reserves startup [in C:\Users\lolip\Desktop\Git projects\uvo-reserves-demo\app\__init__.py:101]
2021-05-11 09:07:55,217 INFO: uvo-reserves startup [in C:\Users\lolip\Desktop\Git projects\uvo-reserves-demo\app\__init__.py:101]
2021-05-11 09:08:11,022 ERROR: Exception on /api/register [POST] [in c:\users\lolip\appdata\local\programs\python\python36\lib\site-packages\flask\app.py:1892]
Traceback (most recent call last):
  File "c:\users\lolip\appdata\local\programs\python\python36\lib\site-packages\sqlalchemy\engine\base.py", line 1277, in _execute_context
    cursor, statement, parameters, context
  File "c:\users\lolip\appdata\local\programs\python\python36\lib\site-packages\sqlalchemy\engine\default.py", line 593, in do_execute
    cursor.execute(statement, parameters)
sqlite3.OperationalError: no such table: user

The above exception was the direct cause of the following exception:

Traceback (most recent call last):
  File "c:\users\lolip\appdata\local\programs\python\python36\lib\site-packages\flask\app.py", line 2447, in wsgi_app
    response = self.full_dispatch_request()
  File "c:\users\lolip\appdata\local\programs\python\python36\lib\site-packages\flask\app.py", line 1952, in full_dispatch_request
    rv = self.handle_user_exception(e)
  File "c:\users\lolip\appdata\local\programs\python\python36\lib\site-packages\flask_cors\extension.py", line 165, in wrapped_function
    return cors_after_request(app.make_response(f(*args, **kwargs)))
  File "c:\users\lolip\appdata\local\programs\python\python36\lib\site-packages\flask\app.py", line 1821, in handle_user_exception
    reraise(exc_type, exc_value, tb)
  File "c:\users\lolip\appdata\local\programs\python\python36\lib\site-packages\flask\_compat.py", line 39, in reraise
    raise value
  File "c:\users\lolip\appdata\local\programs\python\python36\lib\site-packages\flask\app.py", line 1950, in full_dispatch_request
    rv = self.dispatch_request()
  File "c:\users\lolip\appdata\local\programs\python\python36\lib\site-packages\flask\app.py", line 1936, in dispatch_request
    return self.view_functions[rule.endpoint](**req.view_args)
  File "C:\Users\lolip\Desktop\Git projects\uvo-reserves-demo\app\api\registration.py", line 16, in register
    return register_user(username, email, password)
  File "C:\Users\lolip\Desktop\Git projects\uvo-reserves-demo\app\services\auth.py", line 38, in register_user
    db.session.commit()
  File "c:\users\lolip\appdata\local\programs\python\python36\lib\site-packages\sqlalchemy\orm\scoping.py", line 163, in do
    return getattr(self.registry(), name)(*args, **kwargs)
  File "c:\users\lolip\appdata\local\programs\python\python36\lib\site-packages\sqlalchemy\orm\session.py", line 1042, in commit
    self.transaction.commit()
  File "c:\users\lolip\appdata\local\programs\python\python36\lib\site-packages\sqlalchemy\orm\session.py", line 504, in commit
    self._prepare_impl()
  File "c:\users\lolip\appdata\local\programs\python\python36\lib\site-packages\sqlalchemy\orm\session.py", line 483, in _prepare_impl
    self.session.flush()
  File "c:\users\lolip\appdata\local\programs\python\python36\lib\site-packages\sqlalchemy\orm\session.py", line 2523, in flush
    self._flush(objects)
  File "c:\users\lolip\appdata\local\programs\python\python36\lib\site-packages\sqlalchemy\orm\session.py", line 2664, in _flush
    transaction.rollback(_capture_exception=True)
  File "c:\users\lolip\appdata\local\programs\python\python36\lib\site-packages\sqlalchemy\util\langhelpers.py", line 69, in __exit__
    exc_value, with_traceback=exc_tb,
  File "c:\users\lolip\appdata\local\programs\python\python36\lib\site-packages\sqlalchemy\util\compat.py", line 182, in raise_
    raise exception
  File "c:\users\lolip\appdata\local\programs\python\python36\lib\site-packages\sqlalchemy\orm\session.py", line 2624, in _flush
    flush_context.execute()
  File "c:\users\lolip\appdata\local\programs\python\python36\lib\site-packages\sqlalchemy\orm\unitofwork.py", line 422, in execute
    rec.execute(self)
  File "c:\users\lolip\appdata\local\programs\python\python36\lib\site-packages\sqlalchemy\orm\unitofwork.py", line 589, in execute
    uow,
  File "c:\users\lolip\appdata\local\programs\python\python36\lib\site-packages\sqlalchemy\orm\persistence.py", line 245, in save_obj
    insert,
  File "c:\users\lolip\appdata\local\programs\python\python36\lib\site-packages\sqlalchemy\orm\persistence.py", line 1136, in _emit_insert_statements
    statement, params
  File "c:\users\lolip\appdata\local\programs\python\python36\lib\site-packages\sqlalchemy\engine\base.py", line 1011, in execute
    return meth(self, multiparams, params)
  File "c:\users\lolip\appdata\local\programs\python\python36\lib\site-packages\sqlalchemy\sql\elements.py", line 298, in _execute_on_connection
    return connection._execute_clauseelement(self, multiparams, params)
  File "c:\users\lolip\appdata\local\programs\python\python36\lib\site-packages\sqlalchemy\engine\base.py", line 1130, in _execute_clauseelement
    distilled_params,
  File "c:\users\lolip\appdata\local\programs\python\python36\lib\site-packages\sqlalchemy\engine\base.py", line 1317, in _execute_context
    e, statement, parameters, cursor, context
  File "c:\users\lolip\appdata\local\programs\python\python36\lib\site-packages\sqlalchemy\engine\base.py", line 1511, in _handle_dbapi_exception
    sqlalchemy_exception, with_traceback=exc_info[2], from_=e
  File "c:\users\lolip\appdata\local\programs\python\python36\lib\site-packages\sqlalchemy\util\compat.py", line 182, in raise_
    raise exception
  File "c:\users\lolip\appdata\local\programs\python\python36\lib\site-packages\sqlalchemy\engine\base.py", line 1277, in _execute_context
    cursor, statement, parameters, context
  File "c:\users\lolip\appdata\local\programs\python\python36\lib\site-packages\sqlalchemy\engine\default.py", line 593, in do_execute
    cursor.execute(statement, parameters)
sqlalchemy.exc.OperationalError: (sqlite3.OperationalError) no such table: user
[SQL: INSERT INTO user (username, email, password, confirmcode, state, last_run_see_time) VALUES (?, ?, ?, ?, ?, ?)]
[parameters: ('testuser', 'testemail@mail.ru', 'pbkdf2:sha256:150000$4RKsOYkG$b060168397f43b545e6018894b4af4a57031e7afa005f684cce39906c5eb252b', None, None, None)]
(Background on this error at: http://sqlalche.me/e/13/e3q8)
2021-05-11 09:08:52,493 INFO: uvo-reserves [in C:\Users\lolip\Desktop\Git projects\uvo-reserves-demo\app\__init__.py:80]
2021-05-11 09:08:52,493 INFO: uvo-reserves startup [in C:\Users\lolip\Desktop\Git projects\uvo-reserves-demo\app\__init__.py:101]
2021-05-11 09:08:52,493 INFO: uvo-reserves startup [in C:\Users\lolip\Desktop\Git projects\uvo-reserves-demo\app\__init__.py:101]
