2021-05-18 18:36:55,070 ERROR: Exception on /api/5/runs [GET] [in c:\users\lolip\desktop\git projects\uvo-reserves-demo\venv\lib\site-packages\flask\app.py:1892]
Traceback (most recent call last):
  File "c:\users\lolip\desktop\git projects\uvo-reserves-demo\venv\lib\site-packages\flask\app.py", line 2447, in wsgi_app
    response = self.full_dispatch_request()
  File "c:\users\lolip\desktop\git projects\uvo-reserves-demo\venv\lib\site-packages\flask\app.py", line 1952, in full_dispatch_request
    rv = self.handle_user_exception(e)
  File "c:\users\lolip\desktop\git projects\uvo-reserves-demo\venv\lib\site-packages\flask_cors\extension.py", line 165, in wrapped_function
    return cors_after_request(app.make_response(f(*args, **kwargs)))
  File "c:\users\lolip\desktop\git projects\uvo-reserves-demo\venv\lib\site-packages\flask\app.py", line 1821, in handle_user_exception
    reraise(exc_type, exc_value, tb)
  File "c:\users\lolip\desktop\git projects\uvo-reserves-demo\venv\lib\site-packages\flask\_compat.py", line 39, in reraise
    raise value
  File "c:\users\lolip\desktop\git projects\uvo-reserves-demo\venv\lib\site-packages\flask\app.py", line 1950, in full_dispatch_request
    rv = self.dispatch_request()
  File "c:\users\lolip\desktop\git projects\uvo-reserves-demo\venv\lib\site-packages\flask\app.py", line 1936, in dispatch_request
    return self.view_functions[rule.endpoint](**req.view_args)
  File "c:\users\lolip\desktop\git projects\uvo-reserves-demo\venv\lib\site-packages\flask_jwt_extended\view_decorators.py", line 121, in decorator
    return fn(*args, **kwargs)
  File "C:\Users\lolip\Desktop\Git projects\uvo-reserves-demo\app\api\run.py", line 17, in get_runs
    'runs': [run.serialize() for run in project_runs]
  File "C:\Users\lolip\Desktop\Git projects\uvo-reserves-demo\app\api\run.py", line 17, in <listcomp>
    'runs': [run.serialize() for run in project_runs]
TypeError: 'dict' object is not callable
2021-05-18 18:37:52,826 INFO: uvo-reserves [in C:\Users\lolip\Desktop\Git projects\uvo-reserves-demo\app\__init__.py:80]
2021-05-18 18:37:52,827 INFO: uvo-reserves startup [in C:\Users\lolip\Desktop\Git projects\uvo-reserves-demo\app\__init__.py:101]
2021-05-18 18:37:52,827 INFO: uvo-reserves startup [in C:\Users\lolip\Desktop\Git projects\uvo-reserves-demo\app\__init__.py:101]
2021-05-18 18:37:53,084 ERROR: Exception on /api/5/runs [GET] [in c:\users\lolip\desktop\git projects\uvo-reserves-demo\venv\lib\site-packages\flask\app.py:1892]
Traceback (most recent call last):
  File "c:\users\lolip\desktop\git projects\uvo-reserves-demo\venv\lib\site-packages\flask\app.py", line 2447, in wsgi_app
    response = self.full_dispatch_request()
  File "c:\users\lolip\desktop\git projects\uvo-reserves-demo\venv\lib\site-packages\flask\app.py", line 1952, in full_dispatch_request
    rv = self.handle_user_exception(e)
  File "c:\users\lolip\desktop\git projects\uvo-reserves-demo\venv\lib\site-packages\flask_cors\extension.py", line 165, in wrapped_function
    return cors_after_request(app.make_response(f(*args, **kwargs)))
  File "c:\users\lolip\desktop\git projects\uvo-reserves-demo\venv\lib\site-packages\flask\app.py", line 1821, in handle_user_exception
    reraise(exc_type, exc_value, tb)
  File "c:\users\lolip\desktop\git projects\uvo-reserves-demo\venv\lib\site-packages\flask\_compat.py", line 39, in reraise
    raise value
  File "c:\users\lolip\desktop\git projects\uvo-reserves-demo\venv\lib\site-packages\flask\app.py", line 1950, in full_dispatch_request
    rv = self.dispatch_request()
  File "c:\users\lolip\desktop\git projects\uvo-reserves-demo\venv\lib\site-packages\flask\app.py", line 1936, in dispatch_request
    return self.view_functions[rule.endpoint](**req.view_args)
  File "c:\users\lolip\desktop\git projects\uvo-reserves-demo\venv\lib\site-packages\flask_jwt_extended\view_decorators.py", line 121, in decorator
    return fn(*args, **kwargs)
  File "C:\Users\lolip\Desktop\Git projects\uvo-reserves-demo\app\api\run.py", line 18, in get_runs
    'runs': [run.serialize() for run in project_runs]
  File "C:\Users\lolip\Desktop\Git projects\uvo-reserves-demo\app\api\run.py", line 18, in <listcomp>
    'runs': [run.serialize() for run in project_runs]
TypeError: 'dict' object is not callable
2021-05-18 18:37:53,084 ERROR: Exception on /api/5/runs [GET] [in c:\users\lolip\desktop\git projects\uvo-reserves-demo\venv\lib\site-packages\flask\app.py:1892]
Traceback (most recent call last):
  File "c:\users\lolip\desktop\git projects\uvo-reserves-demo\venv\lib\site-packages\flask\app.py", line 2447, in wsgi_app
    response = self.full_dispatch_request()
  File "c:\users\lolip\desktop\git projects\uvo-reserves-demo\venv\lib\site-packages\flask\app.py", line 1952, in full_dispatch_request
    rv = self.handle_user_exception(e)
  File "c:\users\lolip\desktop\git projects\uvo-reserves-demo\venv\lib\site-packages\flask_cors\extension.py", line 165, in wrapped_function
    return cors_after_request(app.make_response(f(*args, **kwargs)))
  File "c:\users\lolip\desktop\git projects\uvo-reserves-demo\venv\lib\site-packages\flask\app.py", line 1821, in handle_user_exception
    reraise(exc_type, exc_value, tb)
  File "c:\users\lolip\desktop\git projects\uvo-reserves-demo\venv\lib\site-packages\flask\_compat.py", line 39, in reraise
    raise value
  File "c:\users\lolip\desktop\git projects\uvo-reserves-demo\venv\lib\site-packages\flask\app.py", line 1950, in full_dispatch_request
    rv = self.dispatch_request()
  File "c:\users\lolip\desktop\git projects\uvo-reserves-demo\venv\lib\site-packages\flask\app.py", line 1936, in dispatch_request
    return self.view_functions[rule.endpoint](**req.view_args)
  File "c:\users\lolip\desktop\git projects\uvo-reserves-demo\venv\lib\site-packages\flask_jwt_extended\view_decorators.py", line 121, in decorator
    return fn(*args, **kwargs)
  File "C:\Users\lolip\Desktop\Git projects\uvo-reserves-demo\app\api\run.py", line 18, in get_runs
    'runs': [run.serialize() for run in project_runs]
  File "C:\Users\lolip\Desktop\Git projects\uvo-reserves-demo\app\api\run.py", line 18, in <listcomp>
    'runs': [run.serialize() for run in project_runs]
TypeError: 'dict' object is not callable
2021-05-18 18:38:09,276 INFO: uvo-reserves [in C:\Users\lolip\Desktop\Git projects\uvo-reserves-demo\app\__init__.py:80]
2021-05-18 18:38:09,276 INFO: uvo-reserves startup [in C:\Users\lolip\Desktop\Git projects\uvo-reserves-demo\app\__init__.py:101]
2021-05-18 18:38:09,276 INFO: uvo-reserves startup [in C:\Users\lolip\Desktop\Git projects\uvo-reserves-demo\app\__init__.py:101]
2021-05-18 18:38:09,726 ERROR: Exception on /api/5/runs [GET] [in c:\users\lolip\desktop\git projects\uvo-reserves-demo\venv\lib\site-packages\flask\app.py:1892]
Traceback (most recent call last):
  File "c:\users\lolip\desktop\git projects\uvo-reserves-demo\venv\lib\site-packages\flask\app.py", line 2447, in wsgi_app
    response = self.full_dispatch_request()
  File "c:\users\lolip\desktop\git projects\uvo-reserves-demo\venv\lib\site-packages\flask\app.py", line 1952, in full_dispatch_request
    rv = self.handle_user_exception(e)
  File "c:\users\lolip\desktop\git projects\uvo-reserves-demo\venv\lib\site-packages\flask_cors\extension.py", line 165, in wrapped_function
    return cors_after_request(app.make_response(f(*args, **kwargs)))
  File "c:\users\lolip\desktop\git projects\uvo-reserves-demo\venv\lib\site-packages\flask\app.py", line 1821, in handle_user_exception
    reraise(exc_type, exc_value, tb)
  File "c:\users\lolip\desktop\git projects\uvo-reserves-demo\venv\lib\site-packages\flask\_compat.py", line 39, in reraise
    raise value
  File "c:\users\lolip\desktop\git projects\uvo-reserves-demo\venv\lib\site-packages\flask\app.py", line 1950, in full_dispatch_request
    rv = self.dispatch_request()
  File "c:\users\lolip\desktop\git projects\uvo-reserves-demo\venv\lib\site-packages\flask\app.py", line 1936, in dispatch_request
    return self.view_functions[rule.endpoint](**req.view_args)
  File "c:\users\lolip\desktop\git projects\uvo-reserves-demo\venv\lib\site-packages\flask_jwt_extended\view_decorators.py", line 121, in decorator
    return fn(*args, **kwargs)
  File "C:\Users\lolip\Desktop\Git projects\uvo-reserves-demo\app\api\run.py", line 16, in get_runs
    print(project_runs[1].serialize())
TypeError: 'dict' object is not callable
2021-05-18 18:38:22,629 INFO: uvo-reserves [in C:\Users\lolip\Desktop\Git projects\uvo-reserves-demo\app\__init__.py:80]
2021-05-18 18:38:22,629 INFO: uvo-reserves startup [in C:\Users\lolip\Desktop\Git projects\uvo-reserves-demo\app\__init__.py:101]
2021-05-18 18:38:22,629 INFO: uvo-reserves startup [in C:\Users\lolip\Desktop\Git projects\uvo-reserves-demo\app\__init__.py:101]
