2021-05-11 09:05:08,524 ERROR: Exception on /api/register [POST] [in c:\users\lolip\appdata\local\programs\python\python36\lib\site-packages\flask\app.py:1892]
Traceback (most recent call last):
  File "c:\users\lolip\appdata\local\programs\python\python36\lib\site-packages\sqlalchemy\engine\base.py", line 2338, in _wrap_pool_connect
    return fn()
  File "c:\users\lolip\appdata\local\programs\python\python36\lib\site-packages\sqlalchemy\pool\base.py", line 364, in connect
    return _ConnectionFairy._checkout(self)
  File "c:\users\lolip\appdata\local\programs\python\python36\lib\site-packages\sqlalchemy\pool\base.py", line 778, in _checkout
    fairy = _ConnectionRecord.checkout(pool)
  File "c:\users\lolip\appdata\local\programs\python\python36\lib\site-packages\sqlalchemy\pool\base.py", line 495, in checkout
    rec = pool._do_get()
  File "c:\users\lolip\appdata\local\programs\python\python36\lib\site-packages\sqlalchemy\pool\impl.py", line 140, in _do_get
    self._dec_overflow()
  File "c:\users\lolip\appdata\local\programs\python\python36\lib\site-packages\sqlalchemy\util\langhelpers.py", line 69, in __exit__
    exc_value, with_traceback=exc_tb,
  File "c:\users\lolip\appdata\local\programs\python\python36\lib\site-packages\sqlalchemy\util\compat.py", line 182, in raise_
    raise exception
  File "c:\users\lolip\appdata\local\programs\python\python36\lib\site-packages\sqlalchemy\pool\impl.py", line 137, in _do_get
    return self._create_connection()
  File "c:\users\lolip\appdata\local\programs\python\python36\lib\site-packages\sqlalchemy\pool\base.py", line 309, in _create_connection
    return _ConnectionRecord(self)
  File "c:\users\lolip\appdata\local\programs\python\python36\lib\site-packages\sqlalchemy\pool\base.py", line 440, in __init__
    self.__connect(first_connect_check=True)
  File "c:\users\lolip\appdata\local\programs\python\python36\lib\site-packages\sqlalchemy\pool\base.py", line 661, in __connect
    pool.logger.debug("Error on connect(): %s", e)
  File "c:\users\lolip\appdata\local\programs\python\python36\lib\site-packages\sqlalchemy\util\langhelpers.py", line 69, in __exit__
    exc_value, with_traceback=exc_tb,
  File "c:\users\lolip\appdata\local\programs\python\python36\lib\site-packages\sqlalchemy\util\compat.py", line 182, in raise_
    raise exception
  File "c:\users\lolip\appdata\local\programs\python\python36\lib\site-packages\sqlalchemy\pool\base.py", line 656, in __connect
    connection = pool._invoke_creator(self)
  File "c:\users\lolip\appdata\local\programs\python\python36\lib\site-packages\sqlalchemy\engine\strategies.py", line 114, in connect
    return dialect.connect(*cargs, **cparams)
  File "c:\users\lolip\appdata\local\programs\python\python36\lib\site-packages\sqlalchemy\engine\default.py", line 493, in connect
    return self.dbapi.connect(*cargs, **cparams)
  File "c:\users\lolip\appdata\local\programs\python\python36\lib\site-packages\psycopg2\__init__.py", line 127, in connect
    conn = _connect(dsn, connection_factory=connection_factory, **kwasync)
psycopg2.OperationalError: could not connect to server: Connection refused (0x0000274D/10061)
	Is the server running on host "localhost" (::1) and accepting
	TCP/IP connections on port 5432?
could not connect to server: Connection refused (0x0000274D/10061)
	Is the server running on host "localhost" (127.0.0.1) and accepting
	TCP/IP connections on port 5432?


The above exception was the direct cause of the following exception:

Traceback (most recent call last):
  File "c:\users\lolip\appdata\local\programs\python\python36\lib\site-packages\flask\app.py", line 2447, in wsgi_app
    response = self.full_dispatch_request()
  File "c:\users\lolip\appdata\local\programs\python\python36\lib\site-packages\flask\app.py", line 1952, in full_dispatch_request
    rv = self.handle_user_exception(e)
  File "c:\users\lolip\appdata\local\programs\python\python36\lib\site-packages\flask_cors\extension.py", line 165, in wrapped_function
    return cors_after_request(app.make_response(f(*args, **kwargs)))
  File "c:\users\lolip\appdata\local\programs\python\python36\lib\site-packages\flask\app.py", line 1821, in handle_user_exception
    reraise(exc_type, exc_value, tb)
  File "c:\users\lolip\appdata\local\programs\python\python36\lib\site-packages\flask\_compat.py", line 39, in reraise
    raise value
  File "c:\users\lolip\appdata\local\programs\python\python36\lib\site-packages\flask\app.py", line 1950, in full_dispatch_request
    rv = self.dispatch_request()
  File "c:\users\lolip\appdata\local\programs\python\python36\lib\site-packages\flask\app.py", line 1936, in dispatch_request
    return self.view_functions[rule.endpoint](**req.view_args)
  File "C:\Users\lolip\Desktop\Git projects\uvo-reserves-demo\app\api\registration.py", line 16, in register
    return register_user(username, email, password)
  File "C:\Users\lolip\Desktop\Git projects\uvo-reserves-demo\app\services\auth.py", line 38, in register_user
    db.session.commit()
  File "c:\users\lolip\appdata\local\programs\python\python36\lib\site-packages\sqlalchemy\orm\scoping.py", line 163, in do
    return getattr(self.registry(), name)(*args, **kwargs)
  File "c:\users\lolip\appdata\local\programs\python\python36\lib\site-packages\sqlalchemy\orm\session.py", line 1042, in commit
    self.transaction.commit()
  File "c:\users\lolip\appdata\local\programs\python\python36\lib\site-packages\sqlalchemy\orm\session.py", line 504, in commit
    self._prepare_impl()
  File "c:\users\lolip\appdata\local\programs\python\python36\lib\site-packages\sqlalchemy\orm\session.py", line 483, in _prepare_impl
    self.session.flush()
  File "c:\users\lolip\appdata\local\programs\python\python36\lib\site-packages\sqlalchemy\orm\session.py", line 2523, in flush
    self._flush(objects)
  File "c:\users\lolip\appdata\local\programs\python\python36\lib\site-packages\sqlalchemy\orm\session.py", line 2664, in _flush
    transaction.rollback(_capture_exception=True)
  File "c:\users\lolip\appdata\local\programs\python\python36\lib\site-packages\sqlalchemy\util\langhelpers.py", line 69, in __exit__
    exc_value, with_traceback=exc_tb,
  File "c:\users\lolip\appdata\local\programs\python\python36\lib\site-packages\sqlalchemy\util\compat.py", line 182, in raise_
    raise exception
  File "c:\users\lolip\appdata\local\programs\python\python36\lib\site-packages\sqlalchemy\orm\session.py", line 2624, in _flush
    flush_context.execute()
  File "c:\users\lolip\appdata\local\programs\python\python36\lib\site-packages\sqlalchemy\orm\unitofwork.py", line 422, in execute
    rec.execute(self)
  File "c:\users\lolip\appdata\local\programs\python\python36\lib\site-packages\sqlalchemy\orm\unitofwork.py", line 589, in execute
    uow,
  File "c:\users\lolip\appdata\local\programs\python\python36\lib\site-packages\sqlalchemy\orm\persistence.py", line 213, in save_obj
    ) in _organize_states_for_save(base_mapper, states, uowtransaction):
  File "c:\users\lolip\appdata\local\programs\python\python36\lib\site-packages\sqlalchemy\orm\persistence.py", line 374, in _organize_states_for_save
    base_mapper, uowtransaction, states
  File "c:\users\lolip\appdata\local\programs\python\python36\lib\site-packages\sqlalchemy\orm\persistence.py", line 1602, in _connections_for_states
    connection = uowtransaction.transaction.connection(base_mapper)
  File "c:\users\lolip\appdata\local\programs\python\python36\lib\site-packages\sqlalchemy\orm\session.py", line 314, in connection
    return self._connection_for_bind(bind, execution_options)
  File "c:\users\lolip\appdata\local\programs\python\python36\lib\site-packages\sqlalchemy\orm\session.py", line 421, in _connection_for_bind
    conn = self._parent._connection_for_bind(bind, execution_options)
  File "c:\users\lolip\appdata\local\programs\python\python36\lib\site-packages\sqlalchemy\orm\session.py", line 433, in _connection_for_bind
    conn = bind._contextual_connect()
  File "c:\users\lolip\appdata\local\programs\python\python36\lib\site-packages\sqlalchemy\engine\base.py", line 2304, in _contextual_connect
    self._wrap_pool_connect(self.pool.connect, None),
  File "c:\users\lolip\appdata\local\programs\python\python36\lib\site-packages\sqlalchemy\engine\base.py", line 2342, in _wrap_pool_connect
    e, dialect, self
  File "c:\users\lolip\appdata\local\programs\python\python36\lib\site-packages\sqlalchemy\engine\base.py", line 1584, in _handle_dbapi_exception_noconnection
    sqlalchemy_exception, with_traceback=exc_info[2], from_=e
  File "c:\users\lolip\appdata\local\programs\python\python36\lib\site-packages\sqlalchemy\util\compat.py", line 182, in raise_
    raise exception
  File "c:\users\lolip\appdata\local\programs\python\python36\lib\site-packages\sqlalchemy\engine\base.py", line 2338, in _wrap_pool_connect
    return fn()
  File "c:\users\lolip\appdata\local\programs\python\python36\lib\site-packages\sqlalchemy\pool\base.py", line 364, in connect
    return _ConnectionFairy._checkout(self)
  File "c:\users\lolip\appdata\local\programs\python\python36\lib\site-packages\sqlalchemy\pool\base.py", line 778, in _checkout
    fairy = _ConnectionRecord.checkout(pool)
  File "c:\users\lolip\appdata\local\programs\python\python36\lib\site-packages\sqlalchemy\pool\base.py", line 495, in checkout
    rec = pool._do_get()
  File "c:\users\lolip\appdata\local\programs\python\python36\lib\site-packages\sqlalchemy\pool\impl.py", line 140, in _do_get
    self._dec_overflow()
  File "c:\users\lolip\appdata\local\programs\python\python36\lib\site-packages\sqlalchemy\util\langhelpers.py", line 69, in __exit__
    exc_value, with_traceback=exc_tb,
  File "c:\users\lolip\appdata\local\programs\python\python36\lib\site-packages\sqlalchemy\util\compat.py", line 182, in raise_
    raise exception
  File "c:\users\lolip\appdata\local\programs\python\python36\lib\site-packages\sqlalchemy\pool\impl.py", line 137, in _do_get
    return self._create_connection()
  File "c:\users\lolip\appdata\local\programs\python\python36\lib\site-packages\sqlalchemy\pool\base.py", line 309, in _create_connection
    return _ConnectionRecord(self)
  File "c:\users\lolip\appdata\local\programs\python\python36\lib\site-packages\sqlalchemy\pool\base.py", line 440, in __init__
    self.__connect(first_connect_check=True)
  File "c:\users\lolip\appdata\local\programs\python\python36\lib\site-packages\sqlalchemy\pool\base.py", line 661, in __connect
    pool.logger.debug("Error on connect(): %s", e)
  File "c:\users\lolip\appdata\local\programs\python\python36\lib\site-packages\sqlalchemy\util\langhelpers.py", line 69, in __exit__
    exc_value, with_traceback=exc_tb,
  File "c:\users\lolip\appdata\local\programs\python\python36\lib\site-packages\sqlalchemy\util\compat.py", line 182, in raise_
    raise exception
  File "c:\users\lolip\appdata\local\programs\python\python36\lib\site-packages\sqlalchemy\pool\base.py", line 656, in __connect
    connection = pool._invoke_creator(self)
  File "c:\users\lolip\appdata\local\programs\python\python36\lib\site-packages\sqlalchemy\engine\strategies.py", line 114, in connect
    return dialect.connect(*cargs, **cparams)
  File "c:\users\lolip\appdata\local\programs\python\python36\lib\site-packages\sqlalchemy\engine\default.py", line 493, in connect
    return self.dbapi.connect(*cargs, **cparams)
  File "c:\users\lolip\appdata\local\programs\python\python36\lib\site-packages\psycopg2\__init__.py", line 127, in connect
    conn = _connect(dsn, connection_factory=connection_factory, **kwasync)
sqlalchemy.exc.OperationalError: (psycopg2.OperationalError) could not connect to server: Connection refused (0x0000274D/10061)
	Is the server running on host "localhost" (::1) and accepting
	TCP/IP connections on port 5432?
could not connect to server: Connection refused (0x0000274D/10061)
	Is the server running on host "localhost" (127.0.0.1) and accepting
	TCP/IP connections on port 5432?

(Background on this error at: http://sqlalche.me/e/13/e3q8)
