2021-04-04 17:14:11,761 ERROR: Exception on /las_uploader [POST] [in c:\users\lolip\desktop\git projects\uvo-reserves-demo\venv\lib\site-packages\flask\app.py:1892]
Traceback (most recent call last):
  File "c:\users\lolip\desktop\git projects\uvo-reserves-demo\venv\lib\site-packages\flask\app.py", line 2447, in wsgi_app
    response = self.full_dispatch_request()
  File "c:\users\lolip\desktop\git projects\uvo-reserves-demo\venv\lib\site-packages\flask\app.py", line 1952, in full_dispatch_request
    rv = self.handle_user_exception(e)
  File "c:\users\lolip\desktop\git projects\uvo-reserves-demo\venv\lib\site-packages\flask_cors\extension.py", line 165, in wrapped_function
    return cors_after_request(app.make_response(f(*args, **kwargs)))
  File "c:\users\lolip\desktop\git projects\uvo-reserves-demo\venv\lib\site-packages\flask\app.py", line 1821, in handle_user_exception
    reraise(exc_type, exc_value, tb)
  File "c:\users\lolip\desktop\git projects\uvo-reserves-demo\venv\lib\site-packages\flask\_compat.py", line 39, in reraise
    raise value
  File "c:\users\lolip\desktop\git projects\uvo-reserves-demo\venv\lib\site-packages\flask\app.py", line 1950, in full_dispatch_request
    rv = self.dispatch_request()
  File "c:\users\lolip\desktop\git projects\uvo-reserves-demo\venv\lib\site-packages\flask\app.py", line 1936, in dispatch_request
    return self.view_functions[rule.endpoint](**req.view_args)
  File "C:\Users\lolip\Desktop\Git projects\uvo-reserves-demo\app\main\routes.py", line 116, in las_uploader
    well_info = read_lasio(filename)
  File "C:\Users\lolip\Desktop\Git projects\uvo-reserves-demo\app\helpers\parser.py", line 34, in read_lasio
    W_i = lasio.read(path_lasio, encoding=enc)
  File "c:\users\lolip\desktop\git projects\uvo-reserves-demo\venv\lib\site-packages\lasio\__init__.py", line 45, in read
    return LASFile(file_ref, **kwargs)
  File "c:\users\lolip\desktop\git projects\uvo-reserves-demo\venv\lib\site-packages\lasio\las.py", line 81, in __init__
    self.read(file_ref, **read_kwargs)
  File "c:\users\lolip\desktop\git projects\uvo-reserves-demo\venv\lib\site-packages\lasio\las.py", line 131, in read
    file_obj, self.encoding = reader.open_file(file_ref, **kwargs)
  File "c:\users\lolip\desktop\git projects\uvo-reserves-demo\venv\lib\site-packages\lasio\reader.py", line 126, in open_file
    file_ref, encoding = open_with_codecs(first_line, **encoding_kwargs)
  File "c:\users\lolip\desktop\git projects\uvo-reserves-demo\venv\lib\site-packages\lasio\reader.py", line 171, in open_with_codecs
    nbytes_test = min(32, os.path.getsize(filename))
  File "c:\users\lolip\appdata\local\programs\python\python36\lib\genericpath.py", line 50, in getsize
    return os.stat(filename).st_size
FileNotFoundError: [WinError 2] Не удается найти указанный файл: '1_logs_0792b55d-674f-4be8-bef9-afaefdf21bbc_file_13_logs_2021-02-19 11_26_16.122924143К.las'
2021-04-04 17:15:11,567 INFO: uvo-reserves [in C:\Users\lolip\Desktop\Git projects\uvo-reserves-demo\app\__init__.py:74]
2021-04-04 17:15:25,810 INFO: uvo-reserves [in C:\Users\lolip\Desktop\Git projects\uvo-reserves-demo\app\__init__.py:74]
2021-04-04 17:15:26,819 ERROR: Exception on /las_uploader [POST] [in c:\users\lolip\desktop\git projects\uvo-reserves-demo\venv\lib\site-packages\flask\app.py:1892]
Traceback (most recent call last):
  File "c:\users\lolip\desktop\git projects\uvo-reserves-demo\venv\lib\site-packages\flask\app.py", line 2447, in wsgi_app
    response = self.full_dispatch_request()
  File "c:\users\lolip\desktop\git projects\uvo-reserves-demo\venv\lib\site-packages\flask\app.py", line 1952, in full_dispatch_request
    rv = self.handle_user_exception(e)
  File "c:\users\lolip\desktop\git projects\uvo-reserves-demo\venv\lib\site-packages\flask_cors\extension.py", line 165, in wrapped_function
    return cors_after_request(app.make_response(f(*args, **kwargs)))
  File "c:\users\lolip\desktop\git projects\uvo-reserves-demo\venv\lib\site-packages\flask\app.py", line 1821, in handle_user_exception
    reraise(exc_type, exc_value, tb)
  File "c:\users\lolip\desktop\git projects\uvo-reserves-demo\venv\lib\site-packages\flask\_compat.py", line 39, in reraise
    raise value
  File "c:\users\lolip\desktop\git projects\uvo-reserves-demo\venv\lib\site-packages\flask\app.py", line 1950, in full_dispatch_request
    rv = self.dispatch_request()
  File "c:\users\lolip\desktop\git projects\uvo-reserves-demo\venv\lib\site-packages\flask\app.py", line 1936, in dispatch_request
    return self.view_functions[rule.endpoint](**req.view_args)
  File "C:\Users\lolip\Desktop\Git projects\uvo-reserves-demo\app\main\routes.py", line 116, in las_uploader
    well_info = read_lasio(filename)
  File "C:\Users\lolip\Desktop\Git projects\uvo-reserves-demo\app\helpers\parser.py", line 34, in read_lasio
    W_i = lasio.read(path_lasio, encoding=enc)
  File "c:\users\lolip\desktop\git projects\uvo-reserves-demo\venv\lib\site-packages\lasio\__init__.py", line 45, in read
    return LASFile(file_ref, **kwargs)
  File "c:\users\lolip\desktop\git projects\uvo-reserves-demo\venv\lib\site-packages\lasio\las.py", line 81, in __init__
    self.read(file_ref, **read_kwargs)
  File "c:\users\lolip\desktop\git projects\uvo-reserves-demo\venv\lib\site-packages\lasio\las.py", line 131, in read
    file_obj, self.encoding = reader.open_file(file_ref, **kwargs)
  File "c:\users\lolip\desktop\git projects\uvo-reserves-demo\venv\lib\site-packages\lasio\reader.py", line 126, in open_file
    file_ref, encoding = open_with_codecs(first_line, **encoding_kwargs)
  File "c:\users\lolip\desktop\git projects\uvo-reserves-demo\venv\lib\site-packages\lasio\reader.py", line 171, in open_with_codecs
    nbytes_test = min(32, os.path.getsize(filename))
  File "c:\users\lolip\appdata\local\programs\python\python36\lib\genericpath.py", line 50, in getsize
    return os.stat(filename).st_size
FileNotFoundError: [WinError 2] Не удается найти указанный файл: '1_logs_044d9405-3937-4509-95f9-f4552111b00b_file_13_logs_2021-02-19 11_26_16.122924143К.las'
2021-04-04 17:16:13,874 INFO: uvo-reserves [in C:\Users\lolip\Desktop\Git projects\uvo-reserves-demo\app\__init__.py:74]
2021-04-04 17:16:16,260 ERROR: Exception on /las_uploader [POST] [in c:\users\lolip\desktop\git projects\uvo-reserves-demo\venv\lib\site-packages\flask\app.py:1892]
Traceback (most recent call last):
  File "c:\users\lolip\desktop\git projects\uvo-reserves-demo\venv\lib\site-packages\flask\app.py", line 2447, in wsgi_app
    response = self.full_dispatch_request()
  File "c:\users\lolip\desktop\git projects\uvo-reserves-demo\venv\lib\site-packages\flask\app.py", line 1952, in full_dispatch_request
    rv = self.handle_user_exception(e)
  File "c:\users\lolip\desktop\git projects\uvo-reserves-demo\venv\lib\site-packages\flask_cors\extension.py", line 165, in wrapped_function
    return cors_after_request(app.make_response(f(*args, **kwargs)))
  File "c:\users\lolip\desktop\git projects\uvo-reserves-demo\venv\lib\site-packages\flask\app.py", line 1821, in handle_user_exception
    reraise(exc_type, exc_value, tb)
  File "c:\users\lolip\desktop\git projects\uvo-reserves-demo\venv\lib\site-packages\flask\_compat.py", line 39, in reraise
    raise value
  File "c:\users\lolip\desktop\git projects\uvo-reserves-demo\venv\lib\site-packages\flask\app.py", line 1950, in full_dispatch_request
    rv = self.dispatch_request()
  File "c:\users\lolip\desktop\git projects\uvo-reserves-demo\venv\lib\site-packages\flask\app.py", line 1936, in dispatch_request
    return self.view_functions[rule.endpoint](**req.view_args)
  File "C:\Users\lolip\Desktop\Git projects\uvo-reserves-demo\app\main\routes.py", line 116, in las_uploader
    well_info = read_lasio(filename)
  File "C:\Users\lolip\Desktop\Git projects\uvo-reserves-demo\app\helpers\parser.py", line 34, in read_lasio
    W_i = lasio.read(path_lasio, encoding=enc)
  File "c:\users\lolip\desktop\git projects\uvo-reserves-demo\venv\lib\site-packages\lasio\__init__.py", line 45, in read
    return LASFile(file_ref, **kwargs)
  File "c:\users\lolip\desktop\git projects\uvo-reserves-demo\venv\lib\site-packages\lasio\las.py", line 81, in __init__
    self.read(file_ref, **read_kwargs)
  File "c:\users\lolip\desktop\git projects\uvo-reserves-demo\venv\lib\site-packages\lasio\las.py", line 131, in read
    file_obj, self.encoding = reader.open_file(file_ref, **kwargs)
  File "c:\users\lolip\desktop\git projects\uvo-reserves-demo\venv\lib\site-packages\lasio\reader.py", line 126, in open_file
    file_ref, encoding = open_with_codecs(first_line, **encoding_kwargs)
  File "c:\users\lolip\desktop\git projects\uvo-reserves-demo\venv\lib\site-packages\lasio\reader.py", line 171, in open_with_codecs
    nbytes_test = min(32, os.path.getsize(filename))
  File "c:\users\lolip\appdata\local\programs\python\python36\lib\genericpath.py", line 50, in getsize
    return os.stat(filename).st_size
FileNotFoundError: [WinError 2] Не удается найти указанный файл: '1_logs_16af0041-4f34-473c-9280-56f60a9ed8f8_file_13_logs_2021-02-19_11_26_16.122924143К.las'
2021-04-04 17:17:18,804 INFO: uvo-reserves [in C:\Users\lolip\Desktop\Git projects\uvo-reserves-demo\app\__init__.py:74]
